Workbook

Sheet Parameterized_Lamp_Failure_Repo
A1: Date | B1: CCMS ID | C1: Region | D1: Zone | E1: Ward | F1: Connected Load | G1: Recorded Load | H1: Non Burning Load | I1: No. of Lights Connected | J1: No. of Non Burning Lights | K1: % Non Burning | L1: Burning % | M1: NB_9 | N1: Total_9 | O1: NB_10 | P1: Total_10 | Q1: NB_15 | R1: Total_15 | S1: NB_18 | T1: Total_18 | U1: NB_20 | V1: Total_20 | W1: NB_21 | X1: Total_21 | Y1: NB_24 | Z1: Total_24 | AA1: NB_25 | AB1: Total_25 | AC1: NB_30 | AD1: Total_30 | AE1: NB_34 | AF1: Total_34 | AG1: NB_35 | AH1: Total_35 | AI1: NB_36 | AJ1: Total_36 | AK1: NB_40 | AL1: Total_40 | AM1: NB_42 | AN1: Total_42 | AO1: NB_45 | AP1: Total_45 | AQ1: NB_48 | AR1: Total_48 | AS1: NB_50 | AT1: Total_50 | AU1: NB_56 | AV1: Total_56 | AW1: NB_60 | AX1: Total_60 | AY1: NB_61 | AZ1: Total_61 | BA1: NB_65 | BB1: Total_65 | BC1: NB_70 | BD1: Total_70 | BE1: NB_72 | BF1: Total_72 | BG1: NB_73 | BH1: Total_73 | BI1: NB_75 | BJ1: Total_75 | BK1: NB_78 | BL1: Total_78 | BM1: NB_80 | BN1: Total_80 | BO1: NB_90 | BP1: Total_90 | BQ1: NB_100 | BR1: Total_100 | BS1: NB_104 | BT1: Total_104 | BU1: NB_105 | BV1: Total_105 | BW1: NB_120 | BX1: Total_120 | BY1: NB_150 | BZ1: Total_150 | CA1: NB_160 | CB1: Total_160 | CC1: NB_173 | CD1: Total_173 | CE1: NB_180 | CF1: Total_180 | CG1: NB_200 | CH1: Total_200 | CI1: NB_210 | CJ1: Total_210 | CK1: NB_220 | CL1: Total_220 | CM1: NB_240 | CN1: Total_240 | CO1: NB_250 | CP1: Total_250 | CQ1: Total_300 | CR1: NB_300 | CS1: Total_360 | CT1: NB_360 | CU1: Total_375 | CV1: NB_375 | CW1: NB_900 | CX1: Total_900
A2: 46307 | B2: SHC3074A00073 | C2: Chengalpattu-PIU | D2: Section-2 | E2: 54-102 | F2: 1950 | G2: 1038 | H2: 900 | I2: 13 | J2: 6 | K2: 0.46153846 | L2: 0.53846154 | M2: 0 | N2: 0 | O2: 0 | P2: 0 | Q2: 0 | R2: 0 | S2: 0 | T2: 0 | U2: 0 | V2: 0 | W2: 0 | X2: 0 | Y2: 0 | Z2: 0 | AA2: 0 | AB2: 0 | AC2: 0 | AD2: 0 | AE2: 0 | AF2: 0 | AG2: 0 | AH2: 0 | AI2: 0 | AJ2: 0 | AK2: 0 | AL2: 0 | AM2: 0 | AN2: 0 | AO2: 0 | AP2: 0 | AQ2: 0 | AR2: 0 | AS2: 0 | AT2: 0 | AU2: 0 | AV2: 0 | AW2: 0 | AX2: 0 | AY2: 0 | AZ2: 0 | BA2: 0 | BB2: 0 | BC2: 0 | BD2: 0 | BE2: 0 | BF2: 0 | BG2: 0 | BH2: 0 | BI2: 0 | BJ2: 0 | BK2: 0 | BL2: 0 | BM2: 0 | BN2: 0 | BO2: 0 | BP2: 0 | BQ2: 0 | BR2: 0 | BS2: 0 | BT2: 0 | BU2: 0 | BV2: 0 | BW2: 0 | BX2: 0 | BY2: 6 | BZ2: 13 | CA2: 0 | CB2: 0 | CC2: 0 | CD2: 0 | CE2: 0 | CF2: 0 | CG2: 0 | CH2: 0 | CI2: 0 | CJ2: 0 | CK2: 0 | CL2: 0 | CM2: 0 | CN2: 0 | CO2: 0 | CP2: 0 | CQ2: 0 | CR2: 0 | CS2: 0 | CT2: 0 | CU2: 0 | CV2: 0 | CW2: 0 | CX2: 0
A3: 46307 | B3: SHC3074A00147 | C3: Chengalpattu-PIU | D3: Section-1 | E3: 28-53 | F3: 9030 | G3: 8245 | H3: 750 | I3: 42 | J3: 3 | K3: 0.071428571 | L3: 0.92857143 | M3: 0 | N3: 0 | O3: 0 | P3: 0 | Q3: 0 | R3: 0 | S3: 0 | T3: 0 | U3: 0 | V3: 0 | W3: 0 | X3: 0 | Y3: 0 | Z3: 0 | AA3: 0 | AB3: 0 | AC3: 0 | AD3: 0 | AE3: 0 | AF3: 0 | AG3: 0 | AH3: 0 | AI3: 0 | AJ3: 0 | AK3: 0 | AL3: 0 | AM3: 0 | AN3: 0 | AO3: 0 | AP3: 0 | AQ3: 0 | AR3: 0 | AS3: 0 | AT3: 0 | AU3: 0 | AV3: 0 | AW3: 0 | AX3: 0 | AY3: 0 | AZ3: 0 | BA3: 0 | BB3: 0 | BC3: 0 | BD3: 0 | BE3: 0 | BF3: 0 | BG3: 0 | BH3: 0 | BI3: 0 | BJ3: 0 | BK3: 0 | BL3: 0 | BM3: 0 | BN3: 0 | BO3: 0 | BP3: 0 | BQ3: 0 | BR3: 0 | BS3: 0 | BT3: 0 | BU3: 0 | BV3: 0 | BW3: 0 | BX3: 0 | BY3: 0 | BZ3: 0 | CA3: 0 | CB3: 0 | CC3: 0 | CD3: 0 | CE3: 0 | CF3: 21 | CG3: 0 | CH3: 0 | CI3: 0 | CJ3: 0 | CK3: 0 | CL3: 0 | CM3: 0 | CN3: 0 | CO3: 3 | CP3: 21 | CQ3: 0 | CR3: 0 | CS3: 0 | CT3: 0 | CU3: 0 | CV3: 0 | CW3: 0 | CX3: 0
A4: 46307 | B4: SHC3074A00009 | C4: Chengalpattu-PIU | D4: Section-3 | E4: 103-120 | F4: 1600 | G4: 1599 | H4: 0 | I4: 6 | J4: 0 | K4: 0 | L4: 1 | M4: 0 | N4: 0 | O4: 0 | P4: 0 | Q4: 0 | R4: 0 | S4: 0 | T4: 0 | U4: 0 | V4: 0 | W4: 0 | X4: 0 | Y4: 0 | Z4: 0 | AA4: 0 | AB4: 0 | AC4: 0 | AD4: 0 | AE4: 0 | AF4: 0 | AG4: 0 | AH4: 0 | AI4: 0 | AJ4: 0 | AK4: 0 | AL4: 0 | AM4: 0 | AN4: 0 | AO4: 0 | AP4: 0 | AQ4: 0 | AR4: 0 | AS4: 0 | AT4: 0 | AU4: 0 | AV4: 0 | AW4: 0 | AX4: 0 | AY4: 0 | AZ4: 0 | BA4: 0 | BB4: 0 | BC4: 0 | BD4: 0 | BE4: 0 | BF4: 0 | BG4: 0 | BH4: 0 | BI4: 0 | BJ4: 0 | BK4: 0 | BL4: 0 | BM4: 0 | BN4: 0 | BO4: 0 | BP4: 0 | BQ4: 0 | BR4: 0 | BS4: 0 | BT4: 0 | BU4: 0 | BV4: 0 | BW4: 0 | BX4: 0 | BY4: 0 | BZ4: 0 | CA4: 0 | CB4: 0 | CC4: 0 | CD4: 0 | CE4: 0 | CF4: 0 | CG4: 0 | CH4: 2 | CI4: 0 | CJ4: 0 | CK4: 0 | CL4: 0 | CM4: 0 | CN4: 0 | CO4: 0 | CP4: 0 | CQ4: 4 | CR4: 0 | CS4: 0 | CT4: 0 | CU4: 0 | CV4: 0 | CW4: 0 | CX4: 0
A5: 46307 | B5: SHC3074A00016 | C5: Chengalpattu-PIU | D5: Section-2 | E5: 54-102 | F5: 2400 | G5: 364 | H5: 0 | I5: 8 | J5: 0 | K5: 0 | L5: 1 | M5: 0 | N5: 0 | O5: 0 | P5: 0 | Q5: 0 | R5: 0 | S5: 0 | T5: 0 | U5: 0 | V5: 0 | W5: 0 | X5: 0 | Y5: 0 | Z5: 0 | AA5: 0 | AB5: 0 | AC5: 0 | AD5: 0 | AE5: 0 | AF5: 0 | AG5: 0 | AH5: 0 | AI5: 0 | AJ5: 0 | AK5: 0 | AL5: 0 | AM5: 0 | AN5: 0 | AO5: 0 | AP5: 0 | AQ5: 0 | AR5: 0 | AS5: 0 | AT5: 0 | AU5: 0 | AV5: 0 | AW5: 0 | AX5: 0 | AY5: 0 | AZ5: 0 | BA5: 0 | BB5: 0 | BC5: 0 | BD5: 0 | BE5: 0 | BF5: 0 | BG5: 0 | BH5: 0 | BI5: 0 | BJ5: 0 | BK5: 0 | BL5: 0 | BM5: 0 | BN5: 0 | BO5: 0 | BP5: 0 | BQ5: 0 | BR5: 0 | BS5: 0 | BT5: 0 | BU5: 0 | BV5: 0 | BW5: 0 | BX5: 0 | BY5: 0 | BZ5: 0 | CA5: 0 | CB5: 0 | CC5: 0 | CD5: 0 | CE5: 0 | CF5: 0 | CG5: 0 | CH5: 0 | CI5: 0 | CJ5: 0 | CK5: 0 | CL5: 0 | CM5: 0 | CN5: 0 | CO5: 0 | CP5: 0 | CQ5: 8 | CR5: 0 | CS5: 0 | CT5: 0 | CU5: 0 | CV5: 0 | CW5: 0 | CX5: 0
A6: 46307 | B6: SHC3074A00101 | C6: Chengalpattu-PIU | D6: Section-1 | E6: 28-53 | F6: 2400 | G6: 2474 | H6: 0 | I6: 8 | J6: 0 | K6: 0 | L6: 1 | M6: 0 | N6: 0 | O6: 0 | P6: 0 | Q6: 0 | R6: 0 | S6: 0 | T6: 0 | U6: 0 | V6: 0 | W6: 0 | X6: 0 | Y6: 0 | Z6: 0 | AA6: 0 | AB6: 0 | AC6: 0 | AD6: 0 | AE6: 0 | AF6: 0 | AG6: 0 | AH6: 0 | AI6: 0 | AJ6: 0 | AK6: 0 | AL6: 0 | AM6: 0 | AN6: 0 | AO6: 0 | AP6: 0 | AQ6: 0 | AR6: 0 | AS6: 0 | AT6: 0 | AU6: 0 | AV6: 0 | AW6: 0 | AX6: 0 | AY6: 0 | AZ6: 0 | BA6: 0 | BB6: 0 | BC6: 0 | BD6: 0 | BE6: 0 | BF6: 0 | BG6: 0 | BH6: 0 | BI6: 0 | BJ6: 0 | BK6: 0 | BL6: 0 | BM6: 0 | BN6: 0 | BO6: 0 | BP6: 0 | BQ6: 0 | BR6: 0 | BS6: 0 | BT6: 0 | BU6: 0 | BV6: 0 | BW6: 0 | BX6: 0 | BY6: 0 | BZ6: 0 | CA6: 0 | CB6: 0 | CC6: 0 | CD6: 0 | CE6: 0 | CF6: 0 | CG6: 0 | CH6: 0 | CI6: 0 | CJ6: 0 | CK6: 0 | CL6: 0 | CM6: 0 | CN6: 0 | CO6: 0 | CP6: 0 | CQ6: 8 | CR6: 0 | CS6: 0 | CT6: 0 | CU6: 0 | CV6: 0 | CW6: 0 | CX6: 0
A7: 46307 | B7: SHC3074A00102 | C7: Chengalpattu-PIU | D7: Section-1 | E7: 28-53 | F7: 2400 | G7: 5 | H7: 0 | I7: 8 | J7: 0 | K7: 0 | L7: 1 | M7: 0 | N7: 0 | O7: 0 | P7: 0 | Q7: 0 | R7: 0 | S7: 0 | T7: 0 | U7: 0 | V7: 0 | W7: 0 | X7: 0 | Y7: 0 | Z7: 0 | AA7: 0 | AB7: 0 | AC7: 0 | AD7: 0 | AE7: 0 | AF7: 0 | AG7: 0 | AH7: 0 | AI7: 0 | AJ7: 0 | AK7: 0 | AL7: 0 | AM7: 0 | AN7: 0 | AO7: 0 | AP7: 0 | AQ7: 0 | AR7: 0 | AS7: 0 | AT7: 0 | AU7: 0 | AV7: 0 | AW7: 0 | AX7: 0 | AY7: 0 | AZ7: 0 | BA7: 0 | BB7: 0 | BC7: 0 | BD7: 0 | BE7: 0 | BF7: 0 | BG7: 0 | BH7: 0 | BI7: 0 | BJ7: 0 | BK7: 0 | BL7: 0 | BM7: 0 | BN7: 0 | BO7: 0 | BP7: 0 | BQ7: 0 | BR7: 0 | BS7: 0 | BT7: 0 | BU7: 0 | BV7: 0 | BW7: 0 | BX7: 0 | BY7: 0 | BZ7: 0 | CA7: 0 | CB7: 0 | CC7: 0 | CD7: 0 | CE7: 0 | CF7: 0 | CG7: 0 | CH7: 0 | CI7: 0 | CJ7: 0 | CK7: 0 | CL7: 0 | CM7: 0 | CN7: 0 | CO7: 0 | CP7: 0 | CQ7: 8 | CR7: 0 | CS7: 0 | CT7: 0 | CU7: 0 | CV7: 0 | CW7: 0 | CX7: 0
A8: 46307 | B8: SHC3074A00082 | C8: Chengalpattu-PIU | D8: Section-2 | E8: 54-102 | F8: 1500 | G8: 1329 | H8: 150 | I8: 10 | J8: 1 | K8: 0.1 | L8: 0.9 | M8: 0 | N8: 0 | O8: 0 | P8: 0 | Q8: 0 | R8: 0 | S8: 0 | T8: 0 | U8: 0 | V8: 0 | W8: 0 | X8: 0 | Y8: 0 | Z8: 0 | AA8: 0 | AB8: 0 | AC8: 0 | AD8: 0 | AE8: 0 | AF8: 0 | AG8: 0 | AH8: 0 | AI8: 0 | AJ8: 0 | AK8: 0 | AL8: 0 | AM8: 0 | AN8: 0 | AO8: 0 | AP8: 0 | AQ8: 0 | AR8: 0 | AS8: 0 | AT8: 0 | AU8: 0 | AV8: 0 | AW8: 0 | AX8: 0 | AY8: 0 | AZ8: 0 | BA8: 0 | BB8: 0 | BC8: 0 | BD8: 0 | BE8: 0 | BF8: 0 | BG8: 0 | BH8: 0 | BI8: 0 | BJ8: 0 | BK8: 0 | BL8: 0 | BM8: 0 | BN8: 0 | BO8: 0 | BP8: 0 | BQ8: 0 | BR8: 0 | BS8: 0 | BT8: 0 | BU8: 0 | BV8: 0 | BW8: 0 | BX8: 0 | BY8: 1 | BZ8: 10 | CA8: 0 | CB8: 0 | CC8: 0 | CD8: 0 | CE8: 0 | CF8: 0 | CG8: 0 | CH8: 0 | CI8: 0 | CJ8: 0 | CK8: 0 | CL8: 0 | CM8: 0 | CN8: 0 | CO8: 0 | CP8: 0 | CQ8: 0 | CR8: 0 | CS8: 0 | CT8: 0 | CU8: 0 | CV8: 0 | CW8: 0 | CX8: 0
A9: 46307 | B9: SHC3074A00110 | C9: Chengalpattu-PIU | D9: Section-2 | E9: 54-102 | F9: 2400 | G9: 2438 | H9: 0 | I9: 8 | J9: 0 | K9: 0 | L9: 1 | M9: 0 | N9: 0 | O9: 0 | P9: 0 | Q9: 0 | R9: 0 | S9: 0 | T9: 0 | U9: 0 | V9: 0 | W9: 0 | X9: 0 | Y9: 0 | Z9: 0 | AA9: 0 | AB9: 0 | AC9: 0 | AD9: 0 | AE9: 0 | AF9: 0 | AG9: 0 | AH9: 0 | AI9: 0 | AJ9: 0 | AK9: 0 | AL9: 0 | AM9: 0 | AN9: 0 | AO9: 0 | AP9: 0 | AQ9: 0 | AR9: 0 | AS9: 0 | AT9: 0 | AU9: 0 | AV9: 0 | AW9: 0 | AX9: 0 | AY9: 0 | AZ9: 0 | BA9: 0 | BB9: 0 | BC9: 0 | BD9: 0 | BE9: 0 | BF9: 0 | BG9: 0 | BH9: 0 | BI9: 0 | BJ9: 0 | BK9: 0 | BL9: 0 | BM9: 0 | BN9: 0 | BO9: 0 | BP9: 0 | BQ9: 0 | BR9: 0 | BS9: 0 | BT9: 0 | BU9: 0 | BV9: 0 | BW9: 0 | BX9: 0 | BY9: 0 | BZ9: 0 | CA9: 0 | CB9: 0 | CC9: 0 | CD9: 0 | CE9: 0 | CF9: 0 | CG9: 0 | CH9: 0 | CI9: 0 | CJ9: 0 | CK9: 0 | CL9: 0 | CM9: 0 | CN9: 0 | CO9: 0 | CP9: 0 | CQ9: 8 | CR9: 0 | CS9: 0 | CT9: 0 | CU9: 0 | CV9: 0 | CW9: 0 | CX9: 0
A10: 46307 | B10: SHC3074A00045 | C10: Chengalpattu-PIU | D10: Section-1 | E10: 28-53 | F10: 8400 | G10: 9326 | H10: 0 | I10: 38 | J10: 0 | K10: 0 | L10: 1 | M10: 0 | N10: 0 | O10: 0 | P10: 0 | Q10: 0 | R10: 0 | S10: 0 | T10: 0 | U10: 0 | V10: 0 | W10: 0 | X10: 0 | Y10: 0 | Z10: 0 | AA10: 0 | AB10: 0 | AC10: 0 | AD10: 0 | AE10: 0 | AF10: 0 | AG10: 0 | AH10: 0 | AI10: 0 | AJ10: 0 | AK10: 0 | AL10: 0 | AM10: 0 | AN10: 0 | AO10: 0 | AP10: 0 | AQ10: 0 | AR10: 0 | AS10: 0 | AT10: 0 | AU10: 0 | AV10: 0 | AW10: 0 | AX10: 0 | AY10: 0 | AZ10: 0 | BA10: 0 | BB10: 0 | BC10: 0 | BD10: 0 | BE10: 0 | BF10: 0 | BG10: 0 | BH10: 0 | BI10: 0 | BJ10: 0 | BK10: 0 | BL10: 0 | BM10: 0 | BN10: 0 | BO10: 0 | BP10: 0 | BQ10: 0 | BR10: 0 | BS10: 0 | BT10: 0 | BU10: 0 | BV10: 0 | BW10: 0 | BX10: 0 | BY10: 0 | BZ10: 0 | CA10: 0 | CB10: 0 | CC10: 0 | CD10: 0 | CE10: 0 | CF10: 0 | CG10: 0 | CH10: 30 | CI10: 0 | CJ10: 0 | CK10: 0 | CL10: 0 | CM10: 0 | CN10: 0 | CO10: 0 | CP10: 0 | CQ10: 8 | CR10: 0 | CS10: 0 | CT10: 0 | CU10: 0 | CV10: 0 | CW10: 0 | CX10: 0
A11: 46307 | B11: SHC3074A00053 | C11: Chengalpattu-PIU | D11: Section-2 | E11: 54-102 | F11: 3900 | G11: 4064 | H11: 0 | I11: 26 | J11: 0 | K11: 0 | L11: 1 | M11: 0 | N11: 0 | O11: 0 | P11: 0 | Q11: 0 | R11: 0 | S11: 0 | T11: 0 | U11: 0 | V11: 0 | W11: 0 | X11: 0 | Y11: 0 | Z11: 0 | AA11: 0 | AB11: 0 | AC11: 0 | AD11: 0 | AE11: 0 | AF11: 0 | AG11: 0 | AH11: 0 | AI11: 0 | AJ11: 0 | AK11: 0 | AL11: 0 | AM11: 0 | AN11: 0 | AO11: 0 | AP11: 0 | AQ11: 0 | AR11: 0 | AS11: 0 | AT11: 0 | AU11: 0 | AV11: 0 | AW11: 0 | AX11: 0 | AY11: 0 | AZ11: 0 | BA11: 0 | BB11: 0 | BC11: 0 | BD11: 0 | BE11: 0 | BF11: 0 | BG11: 0 | BH11: 0 | BI11: 0 | BJ11: 0 | BK11: 0 | BL11: 0 | BM11: 0 | BN11: 0 | BO11: 0 | BP11: 0 | BQ11: 0 | BR11: 0 | BS11: 0 | BT11: 0 | BU11: 0 | BV11: 0 | BW11: 0 | BX11: 0 | BY11: 0 | BZ11: 26 | CA11: 0 | CB11: 0 | CC11: 0 | CD11: 0 | CE11: 0 | CF11: 0 | CG11: 0 | CH11: 0 | CI11: 0 | CJ11: 0 | CK11: 0 | CL11: 0 | CM11: 0 | CN11: 0 | CO11: 0 | CP11: 0 | CQ11: 0 | CR11: 0 | CS11: 0 | CT11: 0 | CU11: 0 | CV11: 0 | CW11: 0 | CX11: 0
A12: 46307 | B12: SHC3074A00005 | C12: Chengalpattu-PIU | D12: Section-2 | E12: 54-102 | F12: 3300 | G12: 2928 | H12: 300 | I12: 11 | J12: 1 | K12: 0.090909091 | L12: 0.90909091 | M12: 0 | N12: 0 | O12: 0 | P12: 0 | Q12: 0 | R12: 0 | S12: 0 | T12: 0 | U12: 0 | V12: 0 | W12: 0 | X12: 0 | Y12: 0 | Z12: 0 | AA12: 0 | AB12: 0 | AC12: 0 | AD12: 0 | AE12: 0 | AF12: 0 | AG12: 0 | AH12: 0 | AI12: 0 | AJ12: 0 | AK12: 0 | AL12: 0 | AM12: 0 | AN12: 0 | AO12: 0 | AP12: 0 | AQ12: 0 | AR12: 0 | AS12: 0 | AT12: 0 | AU12: 0 | AV12: 0 | AW12: 0 | AX12: 0 | AY12: 0 | AZ12: 0 | BA12: 0 | BB12: 0 | BC12: 0 | BD12: 0 | BE12: 0 | BF12: 0 | BG12: 0 | BH12: 0 | BI12: 0 | BJ12: 0 | BK12: 0 | BL12: 0 | BM12: 0 | BN12: 0 | BO12: 0 | BP12: 0 | BQ12: 0 | BR12: 0 | BS12: 0 | BT12: 0 | BU12: 0 | BV12: 0 | BW12: 0 | BX12: 0 | BY12: 0 | BZ12: 0 | CA12: 0 | CB12: 0 | CC12: 0 | CD12: 0 | CE12: 0 | CF12: 0 | CG12: 0 | CH12: 0 | CI12: 0 | CJ12: 0 | CK12: 0 | CL12: 0 | CM12: 0 | CN12: 0 | CO12: 0 | CP12: 0 | CQ12: 11 | CR12: 1 | CS12: 0 | CT12: 0 | CU12: 0 | CV12: 0 | CW12: 0 | CX12: 0
A13: 46307 | B13: SHC3074A00106 | C13: Chengalpattu-PIU | D13: Section-1 | E13: 28-53 | F13: 2400 | G13: 2461 | H13: 0 | I13: 8 | J13: 0 | K13: 0 | L13: 1 | M13: 0 | N13: 0 | O13: 0 | P13: 0 | Q13: 0 | R13: 0 | S13: 0 | T13: 0 | U13: 0 | V13: 0 | W13: 0 | X13: 0 | Y13: 0 | Z13: 0 | AA13: 0 | AB13: 0 | AC13: 0 | AD13: 0 | AE13: 0 | AF13: 0 | AG13: 0 | AH13: 0 | AI13: 0 | AJ13: 0 | AK13: 0 | AL13: 0 | AM13: 0 | AN13: 0 | AO13: 0 | AP13: 0 | AQ13: 0 | AR13: 0 | AS13: 0 | AT13: 0 | AU13: 0 | AV13: 0 | AW13: 0 | AX13: 0 | AY13: 0 | AZ13: 0 | BA13: 0 | BB13: 0 | BC13: 0 | BD13: 0 | BE13: 0 | BF13: 0 | BG13: 0 | BH13: 0 | BI13: 0 | BJ13: 0 | BK13: 0 | BL13: 0 | BM13: 0 | BN13: 0 | BO13: 0 | BP13: 0 | BQ13: 0 | BR13: 0 | BS13: 0 | BT13: 0 | BU13: 0 | BV13: 0 | BW13: 0 | BX13: 0 | BY13: 0 | BZ13: 0 | CA13: 0 | CB13: 0 | CC13: 0 | CD13: 0 | CE13: 0 | CF13: 0 | CG13: 0 | CH13: 0 | CI13: 0 | CJ13: 0 | CK13: 0 | CL13: 0 | CM13: 0 | CN13: 0 | CO13: 0 | CP13: 0 | CQ13: 8 | CR13: 0 | CS13: 0 | CT13: 0 | CU13: 0 | CV13: 0 | CW13: 0 | CX13: 0
... A107: 46307 | B107: SHC3074A00061 | C107: Chengalpattu-PIU | D107: Section-1 | E107: 28-53 | F107: 10750 | G107: 10320 | H107: 430 | I107: 50 | J107: 2 | K107: 0.04 | L107: 0.96 | M107: 0 | N107: 0 | O107: 0 | P107: 0 | Q107: 0 | R107: 0 | S107: 0 | T107: 0 | U107: 0 | V107: 0 | W107: 0 | X107: 0 | Y107: 0 | Z107: 0 | AA107: 0 | AB107: 0 | AC107: 0 | AD107: 0 | AE107: 0 | AF107: 0 | AG107: 0 | AH107: 0 | AI107: 0 | AJ107: 0 | AK107: 0 | AL107: 0 | AM107: 0 | AN107: 0 | AO107: 0 | AP107: 0 | AQ107: 0 | AR107: 0 | AS107: 0 | AT107: 0 | AU107: 0 | AV107: 0 | AW107: 0 | AX107: 0 | AY107: 0 | AZ107: 0 | BA107: 0 | BB107: 0 | BC107: 0 | BD107: 0 | BE107: 0 | BF107: 0 | BG107: 0 | BH107: 0 | BI107: 0 | BJ107: 0 | BK107: 0 | BL107: 0 | BM107: 0 | BN107: 0 | BO107: 0 | BP107: 0 | BQ107: 0 | BR107: 0 | BS107: 0 | BT107: 0 | BU107: 0 | BV107: 0 | BW107: 0 | BX107: 0 | BY107: 0 | BZ107: 0 | CA107: 0 | CB107: 0 | CC107: 0 | CD107: 0 | CE107: 1 | CF107: 25 | CG107: 0 | CH107: 0 | CI107: 0 | CJ107: 0 | CK107: 0 | CL107: 0 | CM107: 0 | CN107: 0 | CO107: 1 | CP107: 25 | CQ107: 0 | CR107: 0 | CS107: 0 | CT107: 0 | CU107: 0 | CV107: 0 | CW107: 0 | CX107: 0

Sheet Sheet 2
B1: NATIONAL HIGHWAYS AUTHORITY OF INDIA (NHAI) - PIU CHENGALPATTU
B2: CCMS STREET LIGHT LAMP FAILURE, BURNING & NON-BURNING % PERFORMANCE DASHBOARD
B3: Operational Date: 12-Oct-2026 | Total CCMS Panels: 106 | Total Lamps: 2,694 | Connected Load: 516.41 kW | Status: LIVE TELEMETRY
B5: TOTAL CCMS MONITORED | D5: TOTAL CONNECTED LAMPS | F5: BURNING LAMPS (ACTIVE) | H5: NON-BURNING (FAILURES) | J5: BURNING RATIO % | L5: NON-BURNING LOAD LOSS
B6: =COUNTA(Parameterized_Lamp_Failure_Repo!B2:B107) | D6: =SUM(Parameterized_Lamp_Failure_Repo!I2:I107) | F6: =D6-H6 | H6: =SUM(Parameterized_Lamp_Failure_Repo!J2:J107) | J6: =F6/D6 | L6: =SUM(Parameterized_Lamp_Failure_Repo!H2:H107)/1000
B7: 106 Online Control Panels | D7: 100% Highway Inventory | F7: 90.65% Burning Ratio | H7: 9.35% Outage Ratio | J7: Network SLA: >95.0% | L7: 51.08 kW Unserved Load
B9: SECTION / ZONE OPERATIONAL PERFORMANCE
B10: Zone / Section | C10: Ward Range | D10: CCMS Panels | E10: Total Lamps | F10: Burning Lamps | G10: Non-Burning | H10: Burning % | I10: Non-Burning % | J10: Connected Load (kW) | K10: Recorded Load (kW) | L10: Deficit Load (kW) | M10: Performance Status | O10: Status | P10: Lamps
B11: Section-1 | C11: 28-53 | D11: =COUNTIF(Parameterized_Lamp_Failure_Repo!$D$2:$D$107, "Section-1") | E11: =SUMIF(Parameterized_Lamp_Failure_Repo!$D$2:$D$107, "Section-1", Parameterized_Lamp_Failure_Repo!$I$2:$I$107) | F11: =E11-G11 | G11: =SUMIF(Parameterized_Lamp_Failure_Repo!$D$2:$D$107, "Section-1", Parameterized_Lamp_Failure_Repo!$J$2:$J$107) | H11: =F11/E11 | I11: =G11/E11 | J11: =SUMIF(Parameterized_Lamp_Failure_Repo!$D$2:$D$107, "Section-1", Parameterized_Lamp_Failure_Repo!$F$2:$F$107)/1000 | K11: =SUMIF(Parameterized_Lamp_Failure_Repo!$D$2:$D$107, "Section-1", Parameterized_Lamp_Failure_Repo!$G$2:$G$107)/1000 | L11: =SUMIF(Parameterized_Lamp_Failure_Repo!$D$2:$D$107, "Section-1", Parameterized_Lamp_Failure_Repo!$H$2:$H$107)/1000 | M11: OPTIMAL (91.98%) | O11: Burning Lights | P11: =F14
B12: Section-2 | C12: 54-102 | D12: =COUNTIF(Parameterized_Lamp_Failure_Repo!$D$2:$D$107, "Section-2") | E12: =SUMIF(Parameterized_Lamp_Failure_Repo!$D$2:$D$107, "Section-2", Parameterized_Lamp_Failure_Repo!$I$2:$I$107) | F12: =E12-G12 | G12: =SUMIF(Parameterized_Lamp_Failure_Repo!$D$2:$D$107, "Section-2", Parameterized_Lamp_Failure_Repo!$J$2:$J$107) | H12: =F12/E12 | I12: =G12/E12 | J12: =SUMIF(Parameterized_Lamp_Failure_Repo!$D$2:$D$107, "Section-2", Parameterized_Lamp_Failure_Repo!$F$2:$F$107)/1000 | K12: =SUMIF(Parameterized_Lamp_Failure_Repo!$D$2:$D$107, "Section-2", Parameterized_Lamp_Failure_Repo!$G$2:$G$107)/1000 | L12: =SUMIF(Parameterized_Lamp_Failure_Repo!$D$2:$D$107, "Section-2", Parameterized_Lamp_Failure_Repo!$H$2:$H$107)/1000 | M12: ATTENTION (88.07%) | O12: Non-Burning Lights | P12: =G14
B13: Section-3 | C13: 103-120 | D13: =COUNTIF(Parameterized_Lamp_Failure_Repo!$D$2:$D$107, "Section-3") | E13: =SUMIF(Parameterized_Lamp_Failure_Repo!$D$2:$D$107, "Section-3", Parameterized_Lamp_Failure_Repo!$I$2:$I$107) | F13: =E13-G13 | G13: =SUMIF(Parameterized_Lamp_Failure_Repo!$D$2:$D$107, "Section-3", Parameterized_Lamp_Failure_Repo!$J$2:$J$107) | H13: =F13/E13 | I13: =G13/E13 | J13: =SUMIF(Parameterized_Lamp_Failure_Repo!$D$2:$D$107, "Section-3", Parameterized_Lamp_Failure_Repo!$F$2:$F$107)/1000 | K13: =SUMIF(Parameterized_Lamp_Failure_Repo!$D$2:$D$107, "Section-3", Parameterized_Lamp_Failure_Repo!$G$2:$G$107)/1000 | L13: =SUMIF(Parameterized_Lamp_Failure_Repo!$D$2:$D$107, "Section-3", Parameterized_Lamp_Failure_Repo!$H$2:$H$107)/1000 | M13: EXCELLENT (100.0%)
B14: TOTAL / NETWORK AVERAGE | C14: All Wards | D14: =SUM(D11:D13) | E14: =SUM(E11:E13) | F14: =SUM(F11:F13) | G14: =SUM(G11:G13) | H14: =F14/E14 | I14: =G14/E14 | J14: =SUM(J11:J13) | K14: =SUM(K11:K13) | L14: =SUM(L11:L13) | M14: 90.65% BURNING | O14: Section | P14: Burning | Q14: Non-Burning
O15: Section-1 | P15: =F11 | Q15: =G11
B16: AVAILABLE LAMP FAILURE ANALYSIS BY WATTAGE (CORRIDOR RATINGS) | L16: CCMS HEALTH TIERS | O16: Section-2 | P16: =F12 | Q16: =G12
B17: Lamp Rating | C17: Total Installed | D17: Burning Lamps | E17: Non-Burning (Failed) | F17: Burning % | G17: Non-Burning % | H17: Outage Share % | I17: Deficit Load (kW) | J17: Replacement Stock Priority | L17: Health Category | M17: Panels (%) | O17: Section-3 | P17: =F13 | Q17: =G13
B18: 150 Watts | C18: =SUM(Parameterized_Lamp_Failure_Repo!$BZ$2:$BZ$107) | D18: =C18-E18 | E18: =SUM(Parameterized_Lamp_Failure_Repo!$BY$2:$BY$107) | F18: =D18/C18 | G18: =E18/C18 | H18: =E18/$E$24 | I18: =E18*0.15 | J18: CRITICAL (51.6% Outage Share) | L18: 100% Burning (Optimal) | M18: 69 Panels (65.1%)
B19: 180 Watts | C19: =SUM(Parameterized_Lamp_Failure_Repo!$CF$2:$CF$107) | D19: =C19-E19 | E19: =SUM(Parameterized_Lamp_Failure_Repo!$CE$2:$CE$107) | F19: =D19/C19 | G19: =E19/C19 | H19: =E19/$E$24 | I19: =E19*0.18 | J19: LOW (0.8% Outage Share) | L19: 90% - 99% Burning (Minor) | M19: 12 Panels (11.3%) | O19: Wattage | P19: Non-Burning
B20: 200 Watts | C20: =SUM(Parameterized_Lamp_Failure_Repo!$CH$2:$CH$107) | D20: =C20-E20 | E20: =SUM(Parameterized_Lamp_Failure_Repo!$CG$2:$CG$107) | F20: =D20/C20 | G20: =E20/C20 | H20: =E20/$E$24 | I20: =E20*0.2 | J20: MEDIUM (4.4% Outage Share) | L20: 70% - 89% Burning (Moderate) | M20: 17 Panels (16.0%) | O20: 150W | P20: =E18
B21: 220 Watts | C21: =SUM(Parameterized_Lamp_Failure_Repo!$CL$2:$CL$107) | D21: =C21-E21 | E21: =SUM(Parameterized_Lamp_Failure_Repo!$CK$2:$CK$107) | F21: =D21/C21 | G21: =E21/C21 | H21: =E21/$E$24 | I21: =E21*0.22 | J21: LOW (2.4% Outage Share) | L21: < 70% Burning (Critical) | M21: 8 Panels (7.5%) | O21: 180W | P21: =E19
B22: 250 Watts | C22: =SUM(Parameterized_Lamp_Failure_Repo!$CP$2:$CP$107) | D22: =C22-E22 | E22: =SUM(Parameterized_Lamp_Failure_Repo!$CO$2:$CO$107) | F22: =D22/C22 | G22: =E22/C22 | H22: =E22/$E$24 | I22: =E22*0.25 | J22: HIGH (25.4% Outage Share) | L22: Total Monitored | M22: 106 Panels (100%) | O22: 200W | P22: =E20
B23: 300 Watts | C23: =SUM(Parameterized_Lamp_Failure_Repo!$CQ$2:$CQ$107) | D23: =C23-E23 | E23: =SUM(Parameterized_Lamp_Failure_Repo!$CR$2:$CR$107) | F23: =D23/C23 | G23: =E23/C23 | H23: =E23/$E$24 | I23: =E23*0.3 | J23: HIGH (15.5% Outage Share) | O23: 220W | P23: =E21
B24: TOTAL AVAILABLE RATINGS | C24: =SUM(C18:C23) | D24: =SUM(D18:D23) | E24: =SUM(E18:E23) | F24: =D24/C24 | G24: =E24/C24 | H24: =SUM(H18:H23) | I24: =SUM(I18:I23) | J24: 252 LAMPS DOWN | O24: 250W | P24: =E22
O25: 300W | P25: =E23
B26: PRIORITY ACTION LIST: TOP CCMS PANELS WITH ACTIVE LAMP FAILURES (IMMEDIATE RECTIFICATION)
B27: Rank | C27: CCMS Panel ID | D27: Section | E27: Ward | F27: Connected Lamps | G27: Non-Burning Lamps | H27: Burning Lamps | I27: Burning % | J27: Non-Burning % | K27: Unserved Load (Watts) | L27: Corridor Impact | M27: Field Action Required
B28: 1 | C28: SHC3074A00026 | D28: Section-1 | E28: 28-53 | F28: 90 | G28: 34 | H28: 56 | I28: 0.6222 | J28: 0.3778 | K28: 8500 | L28: CRITICAL OUTAGE | M28: Replace 34x 250W lamps & check phase-R
B29: 2 | C29: SHC3074A00091 | D29: Section-2 | E29: 54-102 | F29: 34 | G29: 26 | H29: 8 | I29: 0.2353 | J29: 0.7647 | K29: 3900 | L29: CRITICAL OUTAGE | M29: Major blackout (76.5% failed). Driver bank check
B30: 3 | C30: SHC3074A00064 | D30: Section-2 | E30: 54-102 | F30: 60 | G30: 22 | H30: 38 | I30: 0.6333 | J30: 0.3667 | K30: 3300 | L30: CRITICAL OUTAGE | M30: Inspect loop feeder cable & 22 fixtures
B31: 4 | C31: SHC3074A00060 | D31: Section-1 | E31: 28-53 | F31: 52 | G31: 19 | H31: 33 | I31: 0.6346 | J31: 0.3654 | K31: 4050 | L31: CRITICAL OUTAGE | M31: Replace 19x 200W/250W luminaires
B32: 5 | C32: SHC3074A00048 | D32: Section-2 | E32: 54-102 | F32: 30 | G32: 18 | H32: 12 | I32: 0.4 | J32: 0.6 | K32: 3900 | L32: CRITICAL OUTAGE | M32: Severe failure (60% down). Replace 18 lamps
B33: 6 | C33: SHC3074A00052 | D33: Section-1 | E33: 28-53 | F33: 52 | G33: 11 | H33: 41 | I33: 0.7885 | J33: 0.2115 | K33: 2680 | L33: HIGH PRIORITY | M33: Inspect circuit-2 and replace 11 fixtures
B34: 7 | C34: SHC3074A00033 | D34: Section-1 | E34: 28-53 | F34: 38 | G34: 11 | H34: 27 | I34: 0.7105 | J34: 0.2895 | K34: 1650 | L34: HIGH PRIORITY | M34: Replace 11x 150W lamps
B35: 8 | C35: SHC3074A00051 | D35: Section-1 | E35: 28-53 | F35: 55 | G35: 10 | H35: 45 | I35: 0.8182 | J35: 0.1818 | K35: 2000 | L35: HIGH PRIORITY | M35: Service pole fixtures 21 to 30
B36: 9 | C36: SHC3074A00079 | D36: Section-2 | E36: 54-102 | F36: 34 | G36: 10 | H36: 24 | I36: 0.7059 | J36: 0.2941 | K36: 1500 | L36: HIGH PRIORITY | M36: Replace 10x 150W lamps
B37: 10 | C37: SHC3074A00072 | D37: Section-2 | E37: 54-102 | F37: 28 | G37: 10 | H37: 18 | I37: 0.6429 | J37: 0.3571 | K37: 1500 | L37: CRITICAL OUTAGE | M37: 35.7% out. Check MCB-2 & replace 10 units
B38: 11 | C38: SHC3074A00055 | D38: Section-1 | E38: 28-53 | F38: 34 | G38: 9 | H38: 25 | I38: 0.7353 | J38: 0.2647 | K38: 2250 | L38: HIGH PRIORITY | M38: Replace 9x 250W lamps & SPD check
B39: 12 | C39: SHC3074A00028 | D39: Section-1 | E39: 28-53 | F39: 42 | G39: 7 | H39: 35 | I39: 0.8333 | J39: 0.1667 | K39: 2100 | L39: MEDIUM PRIORITY | M39: Replace 7x 300W fixtures
... B42: 15 | C42: SHC3074A00019 | D42: Section-2 | E42: 54-102 | F42: 26 | G42: 5 | H42: 21 | I42: 0.8077 | J42: 0.1923 | K42: 1350 | L42: MEDIUM PRIORITY | M42: Replace 5x 250W lamps
B43: SUBTOTAL | C43: Top 15 Problem Panels | D43: - | E43: - | F43: =SUM(F28:F42) | G43: =SUM(G28:G42) | H43: =SUM(H28:H42) | I43: =H43/F43 | J43: =G43/F43 | K43: =SUM(K28:K42) | L43: 76.2% OF ALL OUTAGES | M43: Resolving these 15 panels lifts network burning rate to 97.77%!
B45: EXECUTIVE SUMMARY REPORT & ENGINEERING OBSERVATIONS
...
